Workbook

Sheet Respuestas de formulario 1
A1: Marca temporal | B1: NOMBRE DE QUIEN REALIZA LA INSPECCIÓN | C1: CONTRATO | D1: CAMPO/COORDINACIÓN | E1: PLACA DEL VEHICULO | F1: KILOMETRAJE | G1: TURNO | H1: **Altas y bajas | I1: **Direccionales derecha e izquierda | J1: **De parqueo | K1: **De freno | L1: **De reversa y alarma de retroceso | M1: **Espejo central y espejos laterales | N1: **Vidrio frontal | O1: Presentación de orden y aseo | P1: Pito | Q1: Sistema de monitoreo GPS | R1: **Cinturones de seguridad | S1: Puertas en buen estado | T1: Vidrios en buen estado | U1: Limpia brisas | V1: Exintor vigente | W1: Botiquín | X1: Estado general de tapicería | Y1: Indicadores (nivel de combustible, temperatura, velocímetro y aceite) | Z1: **Verificar la ausencia de objetos sueltos en la cabina que puedan distraer al conductor | AA1: **Frenos | AB1: **Freno de emergencia o de mano | AC1: **Fugas de aire (movil 100) | AD1: **Control fugas de aire (movil 100) | AE1: **Candados y Bandas (movil 100) | AF1: **Acoples para tomas eléctricas y de aire (movil 100) | AG1: **Niveles de fluidos aceite motor | AH1: **Nivel de fluido de frenos | AI1: **Nivel de fluido de dirección hidraúlica | AJ1: **Nivel de fluido refrigerante | AK1: Nivel de fluido limpia parabrisas | AL1: Estado de correas | AM1: Estado de baterías, cables, conexiones | AN1: **Llantas - Labrado (min 3mm de labrado) | AO1: **Llantas - Sin cortaduras y sin abultamientos | AP1: Llanta de repuesto | AQ1: **Copas o pernos de sujeción de las llantas | AR1: **Suspensión (terminales) | AS1: **Dirección (terminales) | AT1: Tapa de tanque de combustible en buen estado | AU1: Equipo de carretera: gato, llave de pernos, herramienta básica, triángulos o conos, bloques, chaleco, señal pare-siga | AV1: Kit ambiental | AW1: Documentación: tecnomecánica y de gases, tarjeta de propiedad, SOAT, licencia de conducción y permiso para conducir interno | AX1: OBSERVACIONES | AY1: ¿Ha dormido al menos 7 horas en las últimas 24 horas? | AZ1: ¿Se encuentra libre de síntomas de fatiga (Somnolencia, dolor de cabeza, irritabilidad)? | BA1: ¿Se siente en condiciones físicas y mentales para conducir? | BB1: ¿Ha consumido medicamentos o sustancias que afecten su estado de alerta?
A2: 45853.492 | B2: Jin Ramírez | C2: MANTENIMIENTO (CONSORCIO SAS-CFP) | D2: DINA | E2: Ttto55 | F2: 104095 | G2: DIURNA | H2: CUMPLE | I2: CUMPLE | J2: CUMPLE | K2: CUMPLE | L2: CUMPLE | M2: CUMPLE | N2: CUMPLE | O2: CUMPLE | P2: CUMPLE | Q2: CUMPLE | R2: CUMPLE | S2: CUMPLE | T2: CUMPLE | U2: CUMPLE | V2: CUMPLE | W2: CUMPLE | X2: CUMPLE | Y2: CUMPLE | Z2: CUMPLE | AA2: CUMPLE | AB2: CUMPLE | AC2: CUMPLE | AD2: CUMPLE | AE2: CUMPLE | AF2: CUMPLE | AG2: CUMPLE | AH2: CUMPLE | AI2: CUMPLE | AJ2: CUMPLE | AK2: CUMPLE | AL2: CUMPLE | AM2: CUMPLE | AN2: CUMPLE | AO2: CUMPLE | AP2: CUMPLE | AQ2: CUMPLE | AR2: CUMPLE | AS2: CUMPLE | AT2: CUMPLE | AU2: CUMPLE | AV2: CUMPLE | AW2: CUMPLE | AX2: * se evidencia ruido en parte delantera, al equalizar el volante en zonas destapadas * Sistema de embrague se encuentra con fallas * Llantas delanteras están en mal estado * Vidrio lado pasajero, no baja | AY2: Cumple | AZ2: Cumple | BA2: Cumple | BB2: No
A3: 45853.672 | B3: Jorge Mosquera | C3: OPERACIÓN | D3: TELLO | E3: Ntq466 | F3: 5212 | G3: DIURNA | H3: CUMPLE | I3: CUMPLE | J3: CUMPLE | K3: CUMPLE | L3: CUMPLE | M3: CUMPLE | N3: CUMPLE | O3: CUMPLE | P3: CUMPLE | Q3: CUMPLE | R3: CUMPLE | S3: CUMPLE | T3: CUMPLE | U3: CUMPLE | V3: CUMPLE | W3: CUMPLE | X3: CUMPLE | Y3: CUMPLE | Z3: CUMPLE | AA3: CUMPLE | AB3: CUMPLE | AC3: CUMPLE | AD3: CUMPLE | AE3: CUMPLE | AF3: CUMPLE | AG3: CUMPLE | AH3: CUMPLE | AI3: CUMPLE | AJ3: CUMPLE | AK3: CUMPLE | AL3: CUMPLE | AM3: CUMPLE | AN3: CUMPLE | AO3: CUMPLE | AP3: CUMPLE | AQ3: CUMPLE | AR3: CUMPLE | AS3: CUMPLE | AT3: CUMPLE | AU3: CUMPLE | AV3: CUMPLE | AW3: CUMPLE | AY3: Cumple | AZ3: Cumple | BA3: Cumple | BB3: Si
A4: 45853.74 | B4: José Ramírez | C4: OPERACIÓN | D4: DINA | E4: THS596 | F4: 62196 | G4: NOCTURNA | H4: CUMPLE | I4: CUMPLE | J4: CUMPLE | K4: CUMPLE | L4: CUMPLE | M4: CUMPLE | N4: CUMPLE | O4: CUMPLE | P4: CUMPLE | Q4: CUMPLE | R4: CUMPLE | S4: CUMPLE | T4: CUMPLE | U4: CUMPLE | V4: CUMPLE | W4: CUMPLE | X4: CUMPLE | Y4: CUMPLE | Z4: CUMPLE | AA4: CUMPLE | AB4: CUMPLE | AC4: CUMPLE | AD4: CUMPLE | AE4: CUMPLE | AF4: CUMPLE | AG4: CUMPLE | AH4: CUMPLE | AI4: CUMPLE | AJ4: CUMPLE | AK4: CUMPLE | AL4: CUMPLE | AM4: CUMPLE | AN4: CUMPLE | AO4: CUMPLE | AP4: CUMPLE | AQ4: CUMPLE | AR4: CUMPLE | AS4: CUMPLE | AT4: CUMPLE | AU4: CUMPLE | AV4: CUMPLE | AW4: CUMPLE | AY4: Cumple | AZ4: Cumple | BA4: Cumple | BB4: No
A5: 45854.243 | B5: Alejandro aguja perez | C5: MANTENIMIENTO (CONSORCIO SAS-CFP) | D5: DINA | E5: Ths544 | F5: 42650 | G5: DIURNA | H5: CUMPLE | I5: CUMPLE | J5: CUMPLE | K5: CUMPLE | L5: CUMPLE | M5: CUMPLE | N5: CUMPLE | O5: CUMPLE | P5: CUMPLE | Q5: CUMPLE | R5: CUMPLE | S5: CUMPLE | T5: CUMPLE | U5: CUMPLE | V5: CUMPLE | W5: CUMPLE | X5: CUMPLE | Y5: CUMPLE | Z5: CUMPLE | AA5: CUMPLE | AB5: CUMPLE | AC5: NO APLICA | AD5: NO APLICA | AE5: NO APLICA | AF5: NO APLICA | AG5: CUMPLE | AH5: CUMPLE | AI5: CUMPLE | AJ5: CUMPLE | AK5: CUMPLE | AL5: CUMPLE | AM5: CUMPLE | AN5: CUMPLE | AO5: CUMPLE | AP5: CUMPLE | AQ5: CUMPLE | AR5: NO CUMPLE | AS5: CUMPLE | AT5: CUMPLE | AU5: CUMPLE | AV5: CUMPLE | AW5: CUMPLE | AX5: Sonido anormal en parte delantera | AY5: Cumple | AZ5: Cumple | BA5: Cumple | BB5: No
A6: 45854.27 | B6: Jhoan Tamayo Perdomo | C6: OPERACIÓN | D6: YAGUARA | E6: THS412 | F6: 37779 | G6: NO APLICA | H6: CUMPLE | I6: CUMPLE | J6: CUMPLE | K6: CUMPLE | L6: CUMPLE | M6: CUMPLE | N6: CUMPLE | O6: CUMPLE | P6: CUMPLE | Q6: NO CUMPLE | R6: CUMPLE | S6: CUMPLE | T6: CUMPLE | U6: CUMPLE | V6: CUMPLE | W6: CUMPLE | X6: CUMPLE | Y6: CUMPLE | Z6: CUMPLE | AA6: CUMPLE | AB6: CUMPLE | AC6: NO APLICA | AD6: NO APLICA | AE6: NO APLICA | AF6: NO APLICA | AG6: CUMPLE | AH6: CUMPLE | AI6: CUMPLE | AJ6: CUMPLE | AK6: CUMPLE | AL6: CUMPLE | AM6: CUMPLE | AN6: CUMPLE | AO6: CUMPLE | AP6: CUMPLE | AQ6: CUMPLE | AR6: CUMPLE | AS6: CUMPLE | AT6: CUMPLE | AU6: CUMPLE | AV6: CUMPLE | AW6: CUMPLE | AY6: Cumple | AZ6: Cumple | BA6: Cumple | BB6: No
A7: 45854.27 | B7: Gerardo ariza | C7: MANTENIMIENTO (CONSORCIO SAS-CFP) | D7: DINA | E7: EQZ742 | F7: 96703 | G7: DIURNA | H7: CUMPLE | I7: CUMPLE | J7: CUMPLE | K7: CUMPLE | L7: CUMPLE | M7: CUMPLE | N7: NO CUMPLE | O7: CUMPLE | P7: CUMPLE | Q7: CUMPLE | R7: CUMPLE | S7: CUMPLE | T7: CUMPLE | U7: CUMPLE | V7: CUMPLE | W7: CUMPLE | X7: CUMPLE | Y7: CUMPLE | Z7: CUMPLE | AA7: CUMPLE | AB7: CUMPLE | AC7: CUMPLE | AD7: CUMPLE | AE7: CUMPLE | AF7: NO APLICA | AG7: CUMPLE | AH7: CUMPLE | AI7: CUMPLE | AJ7: CUMPLE | AK7: CUMPLE | AL7: CUMPLE | AM7: CUMPLE | AN7: CUMPLE | AO7: CUMPLE | AP7: CUMPLE | AQ7: CUMPLE | AR7: CUMPLE | AS7: CUMPLE | AT7: CUMPLE | AU7: CUMPLE | AV7: CUMPLE | AW7: CUMPLE | AX7: Pendiente cambio panorámico, suministrar herramienta básicas, llantas traceras pequeñas, vías en mal estado, Pendiente cambio sensor de combustible, lavado general | AY7: Cumple | AZ7: Cumple | BA7: Cumple | BB7: No
A8: 45854.272 | B8: Juan Diego Cabrera | C8: OPERACIÓN | D8: SAN FRANCISCO | E8: THQ 021 | F8: 91550 | G8: DIURNA | H8: CUMPLE | I8: CUMPLE | J8: CUMPLE | K8: CUMPLE | L8: CUMPLE | M8: CUMPLE | N8: CUMPLE | O8: CUMPLE | P8: CUMPLE | Q8: CUMPLE | R8: CUMPLE | S8: CUMPLE | T8: CUMPLE | U8: CUMPLE | V8: CUMPLE | W8: CUMPLE | X8: CUMPLE | Y8: CUMPLE | Z8: CUMPLE | AA8: CUMPLE | AB8: CUMPLE | AC8: NO APLICA | AD8: NO APLICA | AE8: NO APLICA | AF8: NO APLICA | AG8: CUMPLE | AH8: CUMPLE | AI8: CUMPLE | AJ8: CUMPLE | AK8: CUMPLE | AL8: CUMPLE | AM8: CUMPLE | AN8: CUMPLE | AO8: CUMPLE | AP8: CUMPLE | AQ8: CUMPLE | AR8: CUMPLE | AS8: CUMPLE | AT8: CUMPLE | AU8: CUMPLE | AV8: CUMPLE | AW8: CUMPLE | AY8: Cumple | AZ8: Cumple | BA8: Cumple | BB8: No
A9: 45854.29 | B9: Betuel olarte dussan | C9: OPERACIÓN | D9: SAN FRANCISCO | E9: WPT277 | F9: 71115 | G9: DIURNA | H9: CUMPLE | I9: CUMPLE | J9: CUMPLE | K9: CUMPLE | L9: CUMPLE | M9: CUMPLE | N9: CUMPLE | O9: CUMPLE | P9: CUMPLE | Q9: CUMPLE | R9: CUMPLE | S9: CUMPLE | T9: CUMPLE | U9: CUMPLE | V9: CUMPLE | W9: CUMPLE | X9: CUMPLE | Y9: CUMPLE | Z9: CUMPLE | AA9: CUMPLE | AB9: CUMPLE | AC9: NO APLICA | AD9: NO APLICA | AE9: NO APLICA | AF9: NO APLICA | AG9: CUMPLE | AH9: CUMPLE | AI9: CUMPLE | AJ9: CUMPLE | AK9: CUMPLE | AL9: CUMPLE | AM9: CUMPLE | AN9: CUMPLE | AO9: CUMPLE | AP9: CUMPLE | AQ9: CUMPLE | AR9: CUMPLE | AS9: CUMPLE | AT9: CUMPLE | AU9: CUMPLE | AV9: CUMPLE | AW9: CUMPLE | AY9: Cumple | AZ9: Cumple | BA9: Cumple | BB9: No
A10: 45854.291 | B10: Arbey Trujillo Castro | C10: OPERACIÓN | D10: YAGUARA | E10: Loz104 | F10: 37121 | G10: DIURNA | H10: CUMPLE | I10: CUMPLE | J10: CUMPLE | K10: CUMPLE | L10: CUMPLE | M10: CUMPLE | N10: CUMPLE | O10: CUMPLE | P10: CUMPLE | Q10: NO CUMPLE | R10: CUMPLE | S10: CUMPLE | T10: CUMPLE | U10: NO CUMPLE | V10: CUMPLE | W10: CUMPLE | X10: CUMPLE | Y10: CUMPLE | Z10: CUMPLE | AA10: CUMPLE | AB10: CUMPLE | AC10: CUMPLE | AD10: CUMPLE | AE10: CUMPLE | AF10: CUMPLE | AG10: CUMPLE | AH10: CUMPLE | AI10: CUMPLE | AJ10: CUMPLE | AK10: CUMPLE | AL10: CUMPLE | AM10: CUMPLE | AN10: CUMPLE | AO10: CUMPLE | AP10: CUMPLE | AQ10: CUMPLE | AR10: CUMPLE | AS10: CUMPLE | AT10: CUMPLE | AU10: CUMPLE | AV10: CUMPLE | AW10: CUMPLE | AY10: Cumple | AZ10: Cumple | BA10: Cumple | BB10: No
A11: 45854.3 | B11: Sergio Barreto | C11: OPERACIÓN | D11: TELLO | E11: THS658 | F11: 851 | G11: DIURNA | H11: CUMPLE | I11: CUMPLE | J11: CUMPLE | K11: CUMPLE | L11: CUMPLE | M11: CUMPLE | N11: CUMPLE | O11: CUMPLE | P11: CUMPLE | Q11: CUMPLE | R11: CUMPLE | S11: CUMPLE | T11: CUMPLE | U11: CUMPLE | V11: CUMPLE | W11: CUMPLE | X11: CUMPLE | Y11: CUMPLE | Z11: CUMPLE | AA11: CUMPLE | AB11: CUMPLE | AC11: NO APLICA | AD11: NO APLICA | AE11: NO APLICA | AF11: NO APLICA | AG11: CUMPLE | AH11: CUMPLE | AI11: CUMPLE | AJ11: CUMPLE | AK11: CUMPLE | AL11: CUMPLE | AM11: CUMPLE | AN11: CUMPLE | AO11: CUMPLE | AP11: CUMPLE | AQ11: CUMPLE | AR11: CUMPLE | AS11: CUMPLE | AT11: CUMPLE | AU11: CUMPLE | AV11: CUMPLE | AW11: CUMPLE | AY11: Cumple | AZ11: Cumple | BA11: Cumple | BB11: No
A12: 45854.306 | B12: Aldemar González Lasso | C12: MANTENIMIENTO (CONSORCIO SAS-CFP) | D12: SAN FRANCISCO | E12: THS530 | F12: 55412 | G12: DIURNA | H12: CUMPLE | I12: CUMPLE | J12: CUMPLE | K12: CUMPLE | L12: CUMPLE | M12: CUMPLE | N12: CUMPLE | O12: CUMPLE | P12: CUMPLE | Q12: CUMPLE | R12: CUMPLE | S12: CUMPLE | T12: CUMPLE | U12: CUMPLE | V12: CUMPLE | W12: CUMPLE | X12: CUMPLE | Y12: CUMPLE | Z12: CUMPLE | AA12: CUMPLE | AB12: CUMPLE | AC12: NO APLICA | AD12: NO APLICA | AE12: NO APLICA | AF12: NO APLICA | AG12: CUMPLE | AH12: CUMPLE | AI12: CUMPLE | AJ12: CUMPLE | AK12: CUMPLE | AL12: CUMPLE | AM12: CUMPLE | AN12: CUMPLE | AO12: CUMPLE | AP12: CUMPLE | AQ12: CUMPLE | AR12: CUMPLE | AS12: CUMPLE | AT12: CUMPLE | AU12: CUMPLE | AV12: CUMPLE | AW12: CUMPLE | AX12: Sin novedad | AY12: Cumple | AZ12: Cumple | BA12: Cumple | BB12: No
A13: 45854.312 | B13: YILBER LOSADA | C13: OPERACIÓN | D13: DINA | E13: WPT278 | F13: 137317 | G13: DIURNA | H13: CUMPLE | I13: CUMPLE | J13: CUMPLE | K13: CUMPLE | L13: CUMPLE | M13: CUMPLE | N13: CUMPLE | O13: CUMPLE | P13: NO CUMPLE | Q13: CUMPLE | R13: CUMPLE | S13: CUMPLE | T13: CUMPLE | U13: CUMPLE | V13: CUMPLE | W13: CUMPLE | X13: CUMPLE | Y13: CUMPLE | Z13: CUMPLE | AA13: CUMPLE | AB13: CUMPLE | AC13: NO APLICA | AD13: NO APLICA | AE13: NO APLICA | AF13: NO APLICA | AG13: CUMPLE | AH13: CUMPLE | AI13: CUMPLE | AJ13: CUMPLE | AK13: CUMPLE | AL13: CUMPLE | AM13: CUMPLE | AN13: CUMPLE | AO13: CUMPLE | AP13: CUMPLE | AQ13: CUMPLE | AR13: CUMPLE | AS13: CUMPLE | AT13: CUMPLE | AU13: CUMPLE | AV13: CUMPLE | AW13: CUMPLE | AX13: Realizar cambio de.aceite Actual 137317 PRO 136913 | AY13: Cumple | AZ13: Cumple | BA13: Cumple | BB13: No
A14: 45854.347 | B14: Leonardo charry charry | C14: OPERACIÓN | D14: DINA | E14: WPT-247 | F14: 106733 | G14: DIURNA | H14: CUMPLE | I14: CUMPLE | J14: CUMPLE | K14: CUMPLE | L14: CUMPLE | M14: CUMPLE | N14: CUMPLE | O14: CUMPLE | P14: CUMPLE | Q14: CUMPLE | R14: CUMPLE | S14: CUMPLE | T14: CUMPLE | U14: CUMPLE | V14: CUMPLE | W14: CUMPLE | X14: CUMPLE | Y14: CUMPLE | Z14: CUMPLE | AA14: CUMPLE | AB14: CUMPLE | AC14: NO APLICA | AD14: NO APLICA | AE14: NO APLICA | AF14: NO APLICA | AG14: CUMPLE | AH14: CUMPLE | AI14: CUMPLE | AJ14: CUMPLE | AK14: CUMPLE | AL14: CUMPLE | AM14: CUMPLE | AN14: CUMPLE | AO14: CUMPLE | AP14: CUMPLE | AQ14: CUMPLE | AR14: CUMPLE | AS14: CUMPLE | AT14: CUMPLE | AU14: CUMPLE | AV14: CUMPLE | AW14: CUMPLE | AX14: La manija de la puerta de izquierda está dañada, el líquido de limpia parabrisas no esa funcionando el filtro está Dañado | AY14: Cumple | AZ14: Cumple | BA14: Cumple | BB14: Si
A15: 45854.365 | B15: DEYMER BORRERO MOSQUERA | C15: OPERACIÓN | D15: TELLO | E15: WPT241 | F15: 60502 | G15: DIURNA | H15: CUMPLE | I15: CUMPLE | J15: CUMPLE | K15: CUMPLE | L15: CUMPLE | M15: CUMPLE | N15: CUMPLE | O15: CUMPLE | P15: CUMPLE | Q15: CUMPLE | R15: CUMPLE | S15: CUMPLE | T15: CUMPLE | U15: CUMPLE | V15: CUMPLE | W15: CUMPLE | X15: CUMPLE | Y15: CUMPLE | Z15: CUMPLE | AA15: CUMPLE | AB15: CUMPLE | AC15: NO APLICA | AD15: NO APLICA | AE15: NO APLICA | AF15: NO APLICA | AG15: CUMPLE | AH15: CUMPLE | AI15: CUMPLE | AJ15: CUMPLE | AK15: CUMPLE | AL15: CUMPLE | AM15: CUMPLE | AN15: CUMPLE | AO15: CUMPLE | AP15: CUMPLE | AQ15: CUMPLE | AR15: CUMPLE | AS15: CUMPLE | AT15: CUMPLE | AU15: CUMPLE | AV15: CUMPLE | AW15: CUMPLE | AY15: Cumple | AZ15: Cumple | BA15: Cumple | BB15: No
A16: 45854.396 | B16: Miller Jesús charry | C16: OPERACIÓN | D16: SAN FRANCISCO | E16: Wpt -245 | F16: 11017 | G16: DIURNA | H16: CUMPLE | I16: CUMPLE | J16: CUMPLE | K16: CUMPLE | L16: CUMPLE | M16: NO CUMPLE | N16: CUMPLE | O16: CUMPLE | P16: CUMPLE | Q16: CUMPLE | R16: CUMPLE | S16: CUMPLE | T16: CUMPLE | U16: CUMPLE | V16: CUMPLE | W16: CUMPLE | X16: CUMPLE | Y16: CUMPLE | Z16: CUMPLE | AA16: CUMPLE | AB16: CUMPLE | AC16: NO APLICA | AD16: NO APLICA | AE16: NO APLICA | AF16: NO APLICA | AG16: CUMPLE | AH16: CUMPLE | AI16: CUMPLE | AJ16: CUMPLE | AK16: CUMPLE | AL16: CUMPLE | AM16: CUMPLE | AN16: CUMPLE | AO16: CUMPLE | AP16: CUMPLE | AQ16: CUMPLE | AR16: CUMPLE | AS16: CUMPLE | AT16: CUMPLE | AU16: CUMPLE | AV16: CUMPLE | AW16: CUMPLE | AX16: Ninguna | AY16: Cumple | AZ16: Cumple | BA16: Cumple | BB16: No
A17: 45854.666 | B17: Jonh edinsson Charry Villarreal | C17: OPERACIÓN | D17: DINA | E17: THQ-137 | F17: 83810 | G17: DIURNA | H17: CUMPLE | I17: CUMPLE | J17: CUMPLE | K17: CUMPLE | L17: CUMPLE | M17: CUMPLE | N17: CUMPLE | O17: CUMPLE | P17: CUMPLE | Q17: CUMPLE | R17: CUMPLE | S17: CUMPLE | T17: CUMPLE | U17: CUMPLE | V17: CUMPLE | W17: CUMPLE | X17: NO CUMPLE | Y17: CUMPLE | Z17: CUMPLE | AA17: CUMPLE | AB17: CUMPLE | AC17: NO APLICA | AD17: NO APLICA | AE17: NO APLICA | AF17: NO APLICA | AG17: CUMPLE | AH17: CUMPLE | AI17: CUMPLE | AJ17: CUMPLE | AK17: CUMPLE | AL17: CUMPLE | AM17: CUMPLE | AN17: CUMPLE | AO17: NO CUMPLE | AP17: NO CUMPLE | AQ17: CUMPLE | AR17: CUMPLE | AS17: CUMPLE | AT17: CUMPLE | AU17: CUMPLE | AV17: CUMPLE | AW17: CUMPLE | AY17: Cumple | AZ17: Cumple | BA17: Cumple | BB17: No
A18: 45854.741 | B18: José Ramírez | C18: OPERACIÓN | D18: DINA | E18: EQQ647 | F18: 220724 | G18: NOCTURNA | H18: CUMPLE | I18: CUMPLE | J18: CUMPLE | K18: CUMPLE | L18: CUMPLE | M18: CUMPLE | N18: CUMPLE | O18: CUMPLE | P18: CUMPLE | Q18: CUMPLE | R18: CUMPLE | S18: CUMPLE | T18: CUMPLE | U18: CUMPLE | V18: CUMPLE | W18: CUMPLE | X18: CUMPLE | Y18: CUMPLE | Z18: CUMPLE | AA18: CUMPLE | AB18: CUMPLE | AC18: CUMPLE | AD18: CUMPLE | AE18: CUMPLE | AF18: CUMPLE | AG18: CUMPLE | AH18: CUMPLE | AI18: CUMPLE | AJ18: CUMPLE | AK18: CUMPLE | AL18: CUMPLE | AM18: CUMPLE | AN18: CUMPLE | AO18: CUMPLE | AP18: CUMPLE | AQ18: CUMPLE | AR18: CUMPLE | AS18: CUMPLE | AT18: CUMPLE | AU18: CUMPLE | AV18: CUMPLE | AW18: CUMPLE | AY18: Cumple | AZ18: Cumple | BA18: Cumple | BB18: No
A19: 45855.27 | B19: DEYMER BORRERO MOSQUERA | C19: OPERACIÓN | D19: TELLO | E19: WPT241 | F19: 60574 | G19: DIURNA | H19: CUMPLE | I19: CUMPLE | J19: CUMPLE | K19: CUMPLE | L19: CUMPLE | M19: CUMPLE | N19: CUMPLE | O19: CUMPLE | P19: CUMPLE | Q19: CUMPLE | R19: CUMPLE | S19: CUMPLE | T19: CUMPLE | U19: CUMPLE | V19: CUMPLE | W19: CUMPLE | X19: CUMPLE | Y19: CUMPLE | Z19: CUMPLE | AA19: CUMPLE | AB19: CUMPLE | AC19: NO APLICA | AD19: NO APLICA | AE19: NO APLICA | AF19: NO APLICA | AG19: CUMPLE | AH19: CUMPLE | AI19: CUMPLE | AJ19: CUMPLE | AK19: CUMPLE | AL19: CUMPLE | AM19: CUMPLE | AN19: CUMPLE | AO19: CUMPLE | AP19: CUMPLE | AQ19: CUMPLE | AR19: CUMPLE | AS19: CUMPLE | AT19: CUMPLE | AU19: CUMPLE | AV19: CUMPLE | AW19: CUMPLE | AY19: Cumple | AZ19: Cumple | BA19: Cumple | BB19: No
A20: 45855.27 | B20: Jhoan Tamayo Perdomo | C20: OPERACIÓN | D20: YAGUARA | E20: THS412 | F20: 37809 | G20: NO APLICA | H20: CUMPLE | I20: CUMPLE | J20: CUMPLE | K20: CUMPLE | L20: CUMPLE | M20: CUMPLE | N20: CUMPLE | O20: CUMPLE | P20: CUMPLE | Q20: NO CUMPLE | R20: CUMPLE | S20: CUMPLE | T20: CUMPLE | U20: CUMPLE | V20: CUMPLE | W20: CUMPLE | X20: CUMPLE | Y20: CUMPLE | Z20: CUMPLE | AA20: CUMPLE | AB20: CUMPLE | AC20: NO APLICA | AD20: NO APLICA | AE20: NO APLICA | AF20: NO APLICA | AG20: CUMPLE | AH20: CUMPLE | AI20: CUMPLE | AJ20: CUMPLE | AK20: CUMPLE | AL20: CUMPLE | AM20: CUMPLE | AN20: CUMPLE | AO20: CUMPLE | AP20: CUMPLE | AQ20: CUMPLE | AR20: CUMPLE | AS20: CUMPLE | AT20: CUMPLE | AU20: CUMPLE | AV20: CUMPLE | AW20: CUMPLE | AY20: Cumple | AZ20: Cumple | BA20: Cumple | BB20: No
A21: 45855.272 | B21: Arbey trujillo | C21: MANTENIMIENTO (CONSORCIO SAS-CFP) | D21: YAGUARA | E21: LPZ104 | F21: 37165 | G21: DIURNA | H21: CUMPLE | I21: CUMPLE | J21: CUMPLE | K21: CUMPLE | L21: CUMPLE | M21: CUMPLE | N21: CUMPLE | O21: CUMPLE | P21: CUMPLE | Q21: CUMPLE | R21: CUMPLE | S21: CUMPLE | T21: CUMPLE | U21: NO CUMPLE | V21: CUMPLE | W21: CUMPLE | X21: CUMPLE | Y21: CUMPLE | Z21: CUMPLE | AA21: CUMPLE | AB21: CUMPLE | AC21: CUMPLE | AD21: CUMPLE | AE21: CUMPLE | AF21: CUMPLE | AG21: CUMPLE | AH21: CUMPLE | AI21: CUMPLE | AJ21: CUMPLE | AK21: CUMPLE | AL21: CUMPLE | AM21: CUMPLE | AN21: CUMPLE | AO21: CUMPLE | AP21: CUMPLE | AQ21: CUMPLE | AR21: CUMPLE | AS21: CUMPLE | AT21: CUMPLE | AU21: CUMPLE | AV21: CUMPLE | AW21: CUMPLE | AY21: Cumple | AZ21: Cumple | BA21: Cumple | BB21: No
A22: 45855.286 | B22: Michelle Aroca Medina | C22: OPERACIÓN | D22: SAN FRANCISCO | E22: WPT 243 | F22: 95892 | G22: DIURNA | H22: CUMPLE | I22: CUMPLE | J22: CUMPLE | K22: CUMPLE | L22: CUMPLE | M22: CUMPLE | N22: CUMPLE | O22: CUMPLE | P22: CUMPLE | Q22: CUMPLE | R22: CUMPLE | S22: CUMPLE | T22: CUMPLE | U22: CUMPLE | V22: CUMPLE | W22: CUMPLE | X22: CUMPLE | Y22: CUMPLE | Z22: CUMPLE | AA22: CUMPLE | AB22: CUMPLE | AC22: NO APLICA | AD22: NO APLICA | AE22: NO APLICA | AF22: NO APLICA | AG22: CUMPLE | AH22: CUMPLE | AI22: CUMPLE | AJ22: CUMPLE | AK22: CUMPLE | AL22: CUMPLE | AM22: CUMPLE | AN22: CUMPLE | AO22: CUMPLE | AP22: CUMPLE | AQ22: CUMPLE | AR22: CUMPLE | AS22: CUMPLE | AT22: CUMPLE | AU22: CUMPLE | AV22: CUMPLE | AW22: CUMPLE | AX22: Hay que bajar el carro para hacer unos ajustes | AY22: Cumple | AZ22: Cumple | BA22: Cumple | BB22: No
A23: 45855.291 | B23: YILBER LOSADA | C23: OPERACIÓN | D23: DINA | E23: WPT278 | F23: 137379 | G23: DIURNA | H23: CUMPLE | I23: CUMPLE | J23: CUMPLE | K23: CUMPLE | L23: CUMPLE | M23: CUMPLE | N23: CUMPLE | O23: CUMPLE | P23: CUMPLE | Q23: CUMPLE | R23: CUMPLE | S23: CUMPLE | T23: CUMPLE | U23: CUMPLE | V23: CUMPLE | W23: CUMPLE | X23: CUMPLE | Y23: CUMPLE | Z23: CUMPLE | AA23: CUMPLE | AB23: CUMPLE | AC23: NO APLICA | AD23: NO APLICA | AE23: NO APLICA | AF23: NO APLICA | AG23: CUMPLE | AH23: CUMPLE | AI23: CUMPLE | AJ23: CUMPLE | AK23: CUMPLE | AL23: CUMPLE | AM23: NO CUMPLE | AN23: CUMPLE | AO23: CUMPLE | AP23: CUMPLE | AQ23: CUMPLE | AR23: CUMPLE | AS23: CUMPLE | AT23: CUMPLE | AU23: CUMPLE | AV23: CUMPLE | AW23: CUMPLE | AX23: Cambionde.aceite Actual 137379 Prox 136913 | AY23: Cumple | AZ23: Cumple | BA23: Cumple | BB23: No
A24: 45855.308 | B24: Sergio Barreto | C24: OPERACIÓN | D24: TELLO | E24: THS658 | F24: 795 | G24: DIURNA | H24: CUMPLE | I24: CUMPLE | J24: CUMPLE | K24: CUMPLE | L24: CUMPLE | M24: CUMPLE | N24: CUMPLE | O24: CUMPLE | P24: CUMPLE | Q24: CUMPLE | R24: CUMPLE | S24: CUMPLE | T24: CUMPLE | U24: CUMPLE | V24: CUMPLE | W24: CUMPLE | X24: CUMPLE | Y24: CUMPLE | Z24: CUMPLE | AA24: CUMPLE | AB24: CUMPLE | AC24: NO APLICA | AD24: NO APLICA | AE24: NO APLICA | AF24: NO APLICA | AG24: CUMPLE | AH24: CUMPLE | AI24: CUMPLE | AJ24: CUMPLE | AK24: CUMPLE | AL24: CUMPLE | AM24: CUMPLE | AN24: CUMPLE | AO24: CUMPLE | AP24: CUMPLE | AQ24: CUMPLE | AR24: CUMPLE | AS24: CUMPLE | AT24: CUMPLE | AU24: CUMPLE | AV24: CUMPLE | AW24: CUMPLE | AY24: Cumple | AZ24: Cumple | BA24: Cumple | BB24: No
A25: 45855.311 | B25: Aldemar González Lasso | C25: MANTENIMIENTO (CONSORCIO SAS-CFP) | D25: SAN FRANCISCO | E25: THS530 | F25: 55456 | G25: DIURNA | H25: CUMPLE | I25: CUMPLE | J25: CUMPLE | K25: CUMPLE | L25: CUMPLE | M25: CUMPLE | N25: CUMPLE | O25: CUMPLE | P25: CUMPLE | Q25: CUMPLE | R25: CUMPLE | S25: CUMPLE | T25: CUMPLE | U25: CUMPLE | V25: CUMPLE | W25: CUMPLE | X25: CUMPLE | Y25: CUMPLE | Z25: CUMPLE | AA25: CUMPLE | AB25: CUMPLE | AC25: NO APLICA | AD25: NO APLICA | AE25: NO APLICA | AF25: NO APLICA | AG25: CUMPLE | AH25: CUMPLE | AI25: CUMPLE | AJ25: CUMPLE | AK25: CUMPLE | AL25: CUMPLE | AM25: CUMPLE | AN25: CUMPLE | AO25: CUMPLE | AP25: CUMPLE | AQ25: CUMPLE | AR25: CUMPLE | AS25: CUMPLE | AT25: CUMPLE | AU25: CUMPLE | AV25: CUMPLE | AW25: CUMPLE | AX25: Sin novedad | AY25: Cumple | AZ25: Cumple | BA25: Cumple | BB25: No
A26: 45855.314 | B26: Rubén cubillos | C26: MANTENIMIENTO (CONSORCIO SAS-CFP) | D26: DINA | E26: THP849 | F26: 130306 | G26: DIURNA | H26: CUMPLE | I26: CUMPLE | J26: CUMPLE | K26: CUMPLE | L26: CUMPLE | M26: CUMPLE | N26: CUMPLE | O26: CUMPLE | P26: CUMPLE | Q26: CUMPLE | R26: CUMPLE | S26: CUMPLE | T26: CUMPLE | U26: CUMPLE | V26: CUMPLE | W26: CUMPLE | X26: CUMPLE | Y26: CUMPLE | Z26: CUMPLE | AA26: CUMPLE | AB26: CUMPLE | AC26: NO APLICA | AD26: NO APLICA | AE26: NO APLICA | AF26: NO APLICA | AG26: CUMPLE | AH26: CUMPLE | AI26: CUMPLE | AJ26: CUMPLE | AK26: CUMPLE | AL26: CUMPLE | AM26: CUMPLE | AN26: CUMPLE | AO26: CUMPLE | AP26: CUMPLE | AQ26: CUMPLE | AR26: CUMPLE | AS26: CUMPLE | AT26: CUMPLE | AU26: CUMPLE | AV26: CUMPLE | AW26: CUMPLE | AY26: Cumple | AZ26: Cumple | BA26: Cumple | BB26: No
A27: 45855.317 | B27: Jonh edinsson Charry Villarreal | C27: OPERACIÓN | D27: DINA | E27: THQ-137 | F27: 83850 | G27: DIURNA | H27: CUMPLE | I27: CUMPLE | J27: CUMPLE | K27: CUMPLE | L27: CUMPLE | M27: CUMPLE | N27: CUMPLE | O27: CUMPLE | P27: CUMPLE | Q27: CUMPLE | R27: CUMPLE | S27: CUMPLE | T27: CUMPLE | U27: CUMPLE | V27: CUMPLE | W27: CUMPLE | X27: NO CUMPLE | Y27: CUMPLE | Z27: CUMPLE | AA27: CUMPLE | AB27: CUMPLE | AC27: NO APLICA | AD27: NO APLICA | AE27: NO APLICA | AF27: NO APLICA | AG27: CUMPLE | AH27: CUMPLE | AI27: CUMPLE | AJ27: CUMPLE | AK27: CUMPLE | AL27: CUMPLE | AM27: CUMPLE | AN27: CUMPLE | AO27: NO CUMPLE | AP27: NO CUMPLE | AQ27: CUMPLE | AR27: CUMPLE | AS27: CUMPLE | AT27: CUMPLE | AU27: CUMPLE | AV27: CUMPLE | AW27: CUMPLE | AY27: Cumple | AZ27: Cumple | BA27: Cumple | BB27: No
A28: 45855.317 | B28: Jorge Lasso diaz | C28: OPERACIÓN | D28: DINA | E28: THQ 136 | F28: 71395 | G28: DIURNA | H28: CUMPLE | I28: CUMPLE | J28: CUMPLE | K28: CUMPLE | L28: CUMPLE | M28: CUMPLE | N28: CUMPLE | O28: CUMPLE | P28: CUMPLE | Q28: CUMPLE | R28: CUMPLE | S28: CUMPLE | T28: CUMPLE | U28: CUMPLE | V28: CUMPLE | W28: CUMPLE | X28: CUMPLE | Y28: CUMPLE | Z28: CUMPLE | AA28: CUMPLE | AB28: CUMPLE | AC28: NO APLICA | AD28: NO APLICA | AE28: NO APLICA | AF28: NO APLICA | AG28: CUMPLE | AH28: CUMPLE | AI28: CUMPLE | AJ28: CUMPLE | AK28: CUMPLE | AL28: CUMPLE | AM28: CUMPLE | AN28: CUMPLE | AO28: CUMPLE | AP28: CUMPLE | AQ28: CUMPLE | AR28: CUMPLE | AS28: CUMPLE | AT28: CUMPLE | AU28: CUMPLE | AV28: CUMPLE | AW28: CUMPLE | AY28: Cumple | AZ28: Cumple | BA28: No cumple | BB28: No
A29: 45855.32 | B29: Wilver Collazos Quiroga | C29: MANTENIMIENTO (CONSORCIO SAS-CFP) | D29: DINA | E29: WPT 239 | F29: 104212 | G29: DIURNA | H29: CUMPLE | I29: CUMPLE | J29: CUMPLE | K29: CUMPLE | L29: CUMPLE | M29: CUMPLE | N29: CUMPLE | O29: CUMPLE | P29: CUMPLE | Q29: CUMPLE | R29: CUMPLE | S29: CUMPLE | T29: CUMPLE | U29: CUMPLE | V29: CUMPLE | W29: CUMPLE | X29: CUMPLE | Y29: CUMPLE | Z29: CUMPLE | AA29: CUMPLE | AB29: CUMPLE | AC29: NO APLICA | AD29: NO APLICA | AE29: NO APLICA | AF29: NO APLICA | AG29: CUMPLE | AH29: CUMPLE | AI29: CUMPLE | AJ29: CUMPLE | AK29: CUMPLE | AL29: CUMPLE | AM29: CUMPLE | AN29: CUMPLE | AO29: CUMPLE | AP29: CUMPLE | AQ29: CUMPLE | AR29: CUMPLE | AS29: CUMPLE | AT29: CUMPLE | AU29: CUMPLE | AV29: CUMPLE | AW29: CUMPLE | AX29: Parabrisas fisurado, se requiere cambio de tuercas de llantas delnteras, rayones leves en cabina por maleza hacía las vías de algunos pozos, el vehículo se le está filtrando el agua lluvia por el vidrio trasero, vías en mal estado y pueden causar daños a partes del vehículo, unidad lateral izquierdo fisurada ya hace más de dos años | AY29: Cumple | AZ29: Cumple | BA29: Cumple | BB29: No
A30: 45855.348 | B30: Javier Alfonso Amaya Suárez | C30: MANTENIMIENTO (CONSORCIO SAS-CFP) | D30: DINA | E30: WPT354 | F30: 123015 | G30: DIURNA | H30: CUMPLE | I30: CUMPLE | J30: CUMPLE | K30: CUMPLE | L30: CUMPLE | M30: CUMPLE | N30: CUMPLE | O30: CUMPLE | P30: CUMPLE | Q30: CUMPLE | R30: CUMPLE | S30: CUMPLE | T30: CUMPLE | U30: CUMPLE | V30: CUMPLE | W30: CUMPLE | X30: CUMPLE | Y30: CUMPLE | Z30: CUMPLE | AA30: CUMPLE | AB30: CUMPLE | AC30: NO APLICA | AD30: NO APLICA | AE30: NO APLICA | AF30: NO APLICA | AG30: CUMPLE | AH30: CUMPLE | AI30: CUMPLE | AJ30: CUMPLE | AK30: CUMPLE | AL30: CUMPLE | AM30: CUMPLE | AN30: CUMPLE | AO30: CUMPLE | AP30: CUMPLE | AQ30: CUMPLE | AR30: CUMPLE | AS30: CUMPLE | AT30: CUMPLE | AU30: CUMPLE | AV30: CUMPLE | AW30: CUMPLE | AX30: Presenta ruido en la correa de accesorios, la silla del copiloto se unde, las llantas traceras están desgastadas, la manija del lado derecho puerta tracera dañada por cristalización de material | AY30: Cumple | AZ30: Cumple | BA30: Cumple | BB30: No
A31: 45855.364 | B31: Leonardo charry charry | C31: OPERACIÓN | D31: DINA | E31: WPT247 | F31: 106742 | G31: DIURNA | H31: CUMPLE | I31: CUMPLE | J31: CUMPLE | K31: CUMPLE | L31: CUMPLE | M31: CUMPLE | N31: CUMPLE | O31: CUMPLE | P31: CUMPLE | Q31: CUMPLE | R31: CUMPLE | S31: CUMPLE | T31: CUMPLE | U31: CUMPLE | V31: CUMPLE | W31: CUMPLE | X31: CUMPLE | Y31: CUMPLE | Z31: CUMPLE | AA31: CUMPLE | AB31: CUMPLE | AC31: NO APLICA | AD31: NO APLICA | AE31: NO APLICA | AF31: NO APLICA | AG31: CUMPLE | AH31: CUMPLE | AI31: CUMPLE | AJ31: CUMPLE | AK31: CUMPLE | AL31: CUMPLE | AM31: CUMPLE | AN31: CUMPLE | AO31: CUMPLE | AP31: CUMPLE | AQ31: CUMPLE | AR31: CUMPLE | AS31: CUMPLE | AT31: CUMPLE | AU31: CUMPLE | AV31: CUMPLE | AW31: CUMPLE | AX31: La manija , del puerta izquierda está dañada, el filtro de agua del limpia vidrio | AY31: Cumple | AZ31: Cumple | BA31: Cumple | BB31: No
A32: 45855.422 | B32: Betuel olarte dussan | C32: OPERACIÓN | D32: SAN FRANCISCO | E32: WPT277 | F32: 71138 | G32: DIURNA | H32: CUMPLE | I32: CUMPLE | J32: CUMPLE | K32: CUMPLE | L32: CUMPLE | M32: CUMPLE | N32: CUMPLE | O32: CUMPLE | P32: CUMPLE | Q32: CUMPLE | R32: CUMPLE | S32: CUMPLE | T32: CUMPLE | U32: CUMPLE | V32: CUMPLE | W32: CUMPLE | X32: CUMPLE | Y32: CUMPLE | Z32: CUMPLE | AA32: CUMPLE | AB32: CUMPLE | AC32: NO APLICA | AD32: NO APLICA | AE32: NO APLICA | AF32: NO APLICA | AG32: CUMPLE | AH32: CUMPLE | AI32: CUMPLE | AJ32: CUMPLE | AK32: CUMPLE | AL32: CUMPLE | AM32: CUMPLE | AN32: CUMPLE | AO32: CUMPLE | AP32: CUMPLE | AQ32: CUMPLE | AR32: CUMPLE | AS32: CUMPLE | AT32: CUMPLE | AU32: CUMPLE | AV32: CUMPLE | AW32: CUMPLE | AY32: Cumple | AZ32: Cumple | BA32: Cumple | BB32: No
A33: 45855.625 | B33: Capitolino mateus | C33: MANTENIMIENTO (CONSORCIO SAS-CFP) | D33: DINA | E33: Eqz286 | F33: 944975 | G33: DIURNA | H33: CUMPLE | I33: CUMPLE | J33: CUMPLE | K33: CUMPLE | L33: CUMPLE | M33: CUMPLE | N33: CUMPLE | O33: CUMPLE | P33: CUMPLE | Q33: CUMPLE | R33: CUMPLE | S33: CUMPLE | T33: CUMPLE | U33: CUMPLE | V33: CUMPLE | W33: CUMPLE | X33: CUMPLE | Y33: CUMPLE | Z33: CUMPLE | AA33: CUMPLE | AB33: CUMPLE | AC33: NO APLICA | AD33: NO APLICA | AE33: NO APLICA | AF33: NO APLICA | AG33: CUMPLE | AH33: CUMPLE | AI33: CUMPLE | AJ33: CUMPLE | AK33: CUMPLE | AL33: CUMPLE | AM33: CUMPLE | AN33: CUMPLE | AO33: CUMPLE | AP33: CUMPLE | AQ33: CUMPLE | AR33: CUMPLE | AS33: CUMPLE | AT33: CUMPLE | AU33: CUMPLE | AV33: CUMPLE | AW33: CUMPLE | AX33: Todo bien | AY33: Cumple | AZ33: Cumple | BA33: Cumple | BB33: No
A34: 45855.628 | B34: Gerardo ariza | C34: MANTENIMIENTO (CONSORCIO SAS-CFP) | D34: DINA | E34: EQZ742 | F34: 65500 | G34: DIURNA | H34: CUMPLE | I34: CUMPLE | J34: CUMPLE | K34: CUMPLE | L34: CUMPLE | M34: CUMPLE | N34: NO CUMPLE | O34: CUMPLE | P34: CUMPLE | Q34: CUMPLE | R34: CUMPLE | S34: CUMPLE | T34: CUMPLE | U34: CUMPLE | V34: CUMPLE | W34: CUMPLE | X34: CUMPLE | Y34: CUMPLE | Z34: CUMPLE | AA34: CUMPLE | AB34: CUMPLE | AC34: CUMPLE | AD34: CUMPLE | AE34: CUMPLE | AF34: NO APLICA | AG34: CUMPLE | AH34: CUMPLE | AI34: CUMPLE | AJ34: CUMPLE | AK34: CUMPLE | AL34: CUMPLE | AM34: CUMPLE | AN34: CUMPLE | AO34: CUMPLE | AP34: CUMPLE | AQ34: CUMPLE | AR34: CUMPLE | AS34: CUMPLE | AT34: CUMPLE | AU34: CUMPLE | AV34: CUMPLE | AW34: CUMPLE | AX34: Pendiente cambio panorámico, suministrar herramienta básicas, llantas traceras pequeñas, vías en mal estado, Pendiente cambio sensor de combustible, lavado general, cambio de.luces laterales,soldadura de.canasta | AY34: Cumple | AZ34: Cumple | BA34: Cumple | BB34: No
A35: 45855.727 | B35: José Ramírez | C35: OPERACIÓN | D35: DINA | E35: EQQ657 | F35: 220818 | G35: NOCTURNA | H35: CUMPLE | I35: CUMPLE | J35: CUMPLE | K35: CUMPLE | L35: CUMPLE | M35: CUMPLE | N35: CUMPLE | O35: CUMPLE | P35: CUMPLE | Q35: CUMPLE | R35: CUMPLE | S35: CUMPLE | T35: CUMPLE | U35: CUMPLE | V35: CUMPLE | W35: CUMPLE | X35: CUMPLE | Y35: CUMPLE | Z35: CUMPLE | AA35: CUMPLE | AB35: CUMPLE | AC35: CUMPLE | AD35: CUMPLE | AE35: CUMPLE | AF35: CUMPLE | AG35: CUMPLE | AH35: CUMPLE | AI35: CUMPLE | AJ35: CUMPLE | AK35: CUMPLE | AL35: CUMPLE | AM35: CUMPLE | AN35: CUMPLE | AO35: CUMPLE | AP35: CUMPLE | AQ35: CUMPLE | AR35: CUMPLE | AS35: CUMPLE | AT35: CUMPLE | AU35: CUMPLE | AV35: CUMPLE | AW35: CUMPLE | AY35: Cumple | AZ35: Cumple | BA35: Cumple | BB35: No
A36: 45856.215 | B36: Jose Miller Escobar Tello | C36: OPERACIÓN | D36: TELLO | E36: Lhw. 521 | F36: 86257 | G36: DIURNA | H36: CUMPLE | I36: CUMPLE | J36: CUMPLE | K36: CUMPLE | L36: CUMPLE | M36: CUMPLE | N36: CUMPLE | O36: CUMPLE | P36: CUMPLE | Q36: CUMPLE | R36: CUMPLE | S36: CUMPLE | T36: CUMPLE | U36: CUMPLE | V36: CUMPLE | W36: CUMPLE | X36: CUMPLE | Y36: CUMPLE | Z36: CUMPLE | AA36: CUMPLE | AB36: CUMPLE | AC36: CUMPLE | AD36: CUMPLE | AE36: CUMPLE | AF36: CUMPLE | AG36: CUMPLE | AH36: CUMPLE | AI36: CUMPLE | AJ36: CUMPLE | AK36: CUMPLE | AL36: CUMPLE | AM36: CUMPLE | AN36: CUMPLE | AO36: CUMPLE | AP36: CUMPLE | AQ36: CUMPLE | AR36: CUMPLE | AS36: CUMPLE | AT36: CUMPLE | AU36: CUMPLE | AV36: CUMPLE | AW36: CUMPLE | AY36: Cumple | AZ36: Cumple | BA36: Cumple | BB36: No
A37: 45856.258 | B37: Betuel olarte dussan | C37: OPERACIÓN | D37: SAN FRANCISCO | E37: WPT277 | F37: 71167 | G37: DIURNA | H37: CUMPLE | I37: CUMPLE | J37: CUMPLE | K37: CUMPLE | L37: CUMPLE | M37: CUMPLE | N37: CUMPLE | O37: CUMPLE | P37: CUMPLE | Q37: CUMPLE | R37: CUMPLE | S37: CUMPLE | T37: CUMPLE | U37: CUMPLE | V37: CUMPLE | W37: CUMPLE | X37: CUMPLE | Y37: CUMPLE | Z37: CUMPLE | AA37: CUMPLE | AB37: CUMPLE | AC37: NO APLICA | AD37: NO APLICA | AE37: NO APLICA | AF37: NO APLICA | AG37: CUMPLE | AH37: CUMPLE | AI37: CUMPLE | AJ37: CUMPLE | AK37: CUMPLE | AL37: CUMPLE | AM37: CUMPLE | AN37: CUMPLE | AO37: CUMPLE | AP37: CUMPLE | AQ37: CUMPLE | AR37: CUMPLE | AS37: CUMPLE | AT37: CUMPLE | AU37: CUMPLE | AV37: CUMPLE | AW37: CUMPLE | AY37: Cumple | AZ37: Cumple | BA37: Cumple | BB37: No
A38: 45856.268 | B38: Jhoan Tamayo Perdomo | C38: OPERACIÓN | D38: YAGUARA | E38: THS412 | F38: 37949 | G38: NO APLICA | H38: CUMPLE | I38: CUMPLE | J38: CUMPLE | K38: CUMPLE | L38: CUMPLE | M38: CUMPLE | N38: CUMPLE | O38: CUMPLE | P38: CUMPLE | Q38: NO CUMPLE | R38: CUMPLE | S38: CUMPLE | T38: CUMPLE | U38: CUMPLE | V38: CUMPLE | W38: CUMPLE | X38: CUMPLE | Y38: CUMPLE | Z38: CUMPLE | AA38: CUMPLE | AB38: CUMPLE | AC38: NO APLICA | AD38: NO APLICA | AE38: NO APLICA | AF38: NO APLICA | AG38: CUMPLE | AH38: CUMPLE | AI38: CUMPLE | AJ38: CUMPLE | AK38: CUMPLE | AL38: CUMPLE | AM38: CUMPLE | AN38: CUMPLE | AO38: CUMPLE | AP38: CUMPLE | AQ38: CUMPLE | AR38: CUMPLE | AS38: CUMPLE | AT38: CUMPLE | AU38: CUMPLE | AV38: CUMPLE | AW38: CUMPLE | AY38: Cumple | AZ38: Cumple | BA38: Cumple | BB38: No
A39: 45856.269 | B39: DEYMER BORRERO MOSQUERA | C39: OPERACIÓN | D39: TELLO | E39: WPT241 | F39: 60646 | G39: DIURNA | H39: CUMPLE | I39: CUMPLE | J39: CUMPLE | K39: CUMPLE | L39: CUMPLE | M39: CUMPLE | N39: CUMPLE | O39: CUMPLE | P39: CUMPLE | Q39: CUMPLE | R39: CUMPLE | S39: CUMPLE | T39: CUMPLE | U39: CUMPLE | V39: CUMPLE | W39: CUMPLE | X39: CUMPLE | Y39: CUMPLE | Z39: CUMPLE | AA39: CUMPLE | AB39: CUMPLE | AC39: NO APLICA | AD39: NO APLICA | AE39: NO APLICA | AF39: NO APLICA | AG39: CUMPLE | AH39: CUMPLE | AI39: CUMPLE | AJ39: CUMPLE | AK39: CUMPLE | AL39: CUMPLE | AM39: CUMPLE | AN39: CUMPLE | AO39: CUMPLE | AP39: CUMPLE | AQ39: CUMPLE | AR39: CUMPLE | AS39: CUMPLE | AT39: CUMPLE | AU39: CUMPLE | AV39: CUMPLE | AW39: CUMPLE | AY39: Cumple | AZ39: Cumple | BA39: Cumple | BB39: No
A40: 45856.275 | B40: Arbey Trujillo Castro | C40: OPERACIÓN | D40: YAGUARA | E40: Lpz1041 | F40: 317216 | G40: DIURNA | H40: CUMPLE | I40: CUMPLE | J40: CUMPLE | K40: CUMPLE | L40: CUMPLE | M40: CUMPLE | N40: CUMPLE | O40: CUMPLE | P40: CUMPLE | Q40: NO CUMPLE | R40: CUMPLE | S40: CUMPLE | T40: CUMPLE | U40: CUMPLE | V40: CUMPLE | W40: CUMPLE | X40: CUMPLE | Y40: CUMPLE | Z40: CUMPLE | AA40: CUMPLE | AB40: CUMPLE | AC40: CUMPLE | AD40: CUMPLE | AE40: CUMPLE | AF40: CUMPLE | AG40: CUMPLE | AH40: CUMPLE | AI40: CUMPLE | AJ40: CUMPLE | AK40: CUMPLE | AL40: CUMPLE | AM40: CUMPLE | AN40: CUMPLE | AO40: CUMPLE | AP40: CUMPLE | AQ40: CUMPLE | AR40: CUMPLE | AS40: CUMPLE | AT40: CUMPLE | AU40: CUMPLE | AV40: CUMPLE | AW40: CUMPLE | AY40: Cumple | AZ40: Cumple | BA40: Cumple | BB40: No
...

Sheet OCTUBRE
A1: Marca temporal | B1: NOMBRE DE QUIEN REALIZA LA INSPECCIÓN | C1: CONTRATO | D1: CAMPO/COORDINACIÓN | E1: PLACA DEL VEHICULO | F1: KILOMETRAJE | G1: TURNO | H1: **Altas y bajas | I1: **Direccionales derecha e izquierda | J1: **De parqueo | K1: **De freno | L1: **De reversa y alarma de retroceso | M1: **Espejo central y espejos laterales | N1: **Vidrio frontal | O1: Presentación de orden y aseo | P1: Pito | Q1: Sistema de monitoreo GPS (Alerta sonora) | R1: **Cinturones de seguridad | S1: Puertas en buen estado | T1: Vidrios en buen estado | U1: Limpia brisas | V1: Exintor vigente | W1: Botiquín | X1: Estado general de tapicería | Y1: Indicadores (nivel de combustible, temperatura, velocímetro y aceite) | Z1: **Verificar la ausencia de objetos sueltos en la cabina que puedan distraer al conductor | AA1: **Frenos | AB1: **Freno de emergencia o de mano | AC1: **Fugas de aire (movil 100) | AD1: **Control fugas de aire (movil 100) | AE1: **Candados y Bandas (movil 100) | AF1: **Acoples para tomas eléctricas y de aire (movil 100) | AG1: **Niveles de fluidos aceite motor | AH1: **Nivel de fluido de frenos | AI1: **Nivel de fluido de dirección hidraúlica | AJ1: **Nivel de fluido refrigerante | AK1: Nivel de fluido limpia parabrisas | AL1: Estado de correas | AM1: Estado de baterías, cables, conexiones | AN1: **Llantas - Labrado (min 3mm de labrado) | AO1: **Llantas - Sin cortaduras y sin abultamientos | AP1: Llanta de repuesto | AQ1: **Copas o pernos de sujeción de las llantas | AR1: **Suspensión (terminales) | AS1: **Dirección (terminales) | AT1: Tapa de tanque de combustible en buen estado | AU1: Equipo de carretera: gato, llave de pernos, herramienta básica, triángulos o conos, bloques, chaleco, señal pare-siga | AV1: Kit ambiental | AW1: Documentación: tecnomecánica y de gases, tarjeta de propiedad, SOAT, licencia de conducción y permiso para conducir interno | AX1: OBSERVACIONES | AY1: ¿Ha dormido al menos 7 horas en las últimas 24 horas? | AZ1: ¿Se encuentra libre de síntomas de fatiga (Somnolencia, dolor de cabeza, irritabilidad)? | BA1: ¿Se siente en condiciones físicas y mentales para conducir? | BB1: ¿Ha consumido medicamentos o sustancias que afecten su estado de alerta?
A2: ='Respuestas de formulario 1'!A1153 -> 45931.257 | B2: ='Respuestas de formulario 1'!B1153 -> Diego Andres Ramírez Mosquera | C2: ='Respuestas de formulario 1'!C1153 -> OPERACIÓN | D2: ='Respuestas de formulario 1'!D1153 -> DINA | E2: ='Respuestas de formulario 1'!E1153 -> EQQ657 | F2: ='Respuestas de formulario 1'!F1153 -> 222410 | G2: ='Respuestas de formulario 1'!G1153 -> DIURNA | H2: ='Respuestas de formulario 1'!H1153 -> CUMPLE | ... BB2: ='Respuestas de formulario 1'!BB1153 -> No
A3: ='Respuestas de formulario 1'!A1154 -> 45931.261 | B3: ='Respuestas de formulario 1'!B1154 -> Arbey trujillo Castro | C3: ='Respuestas de formulario 1'!C1154 -> OPERACIÓN | D3: ='Respuestas de formulario 1'!D1154 -> YAGUARA | E3: ='Respuestas de formulario 1'!E1154 -> WCZ611 | F3: ='Respuestas de formulario 1'!F1154 -> 84975 | G3: ='Respuestas de formulario 1'!G1154 -> DIURNA | H3: ='Respuestas de formulario 1'!H1154 -> CUMPLE | ... BB3: ='Respuestas de formulario 1'!BB1154 -> No
A4: ='Respuestas de formulario 1'!A1155 -> 45931.269 | B4: ='Respuestas de formulario 1'!B1155 -> Jhoan Tamayo Perdomo | C4: ='Respuestas de formulario 1'!C1155 -> OPERACIÓN | D4: ='Respuestas de formulario 1'!D1155 -> YAGUARA | E4: ='Respuestas de formulario 1'!E1155 -> THS412 | F4: ='Respuestas de formulario 1'!F1155 -> 40144 | G4: ='Respuestas de formulario 1'!G1155 -> NO APLICA | H4: ='Respuestas de formulario 1'!H1155 -> CUMPLE | ... BB4: ='Respuestas de formulario 1'!BB1155 -> No
A5: ='Respuestas de formulario 1'!A1156 -> 45931.269 | B5: ='Respuestas de formulario 1'!B1156 -> Carlos Alberto Huepe | C5: ='Respuestas de formulario 1'!C1156 -> MANTENIMIENTO (CONSORCIO SAS-CFP) | D5: ='Respuestas de formulario 1'!D1156 -> TELLO | E5: ='Respuestas de formulario 1'!E1156 -> THS082 | F5: ='Respuestas de formulario 1'!F1156 -> 176978 | G5: ='Respuestas de formulario 1'!G1156 -> DIURNA | H5: ='Respuestas de formulario 1'!H1156 -> CUMPLE | ... BB5: ='Respuestas de formulario 1'!BB1156 -> No
A6: ='Respuestas de formulario 1'!A1157 -> 45931.283 | B6: ='Respuestas de formulario 1'!B1157 -> Jonh edinsson Charry Villarreal | C6: ='Respuestas de formulario 1'!C1157 -> OPERACIÓN | D6: ='Respuestas de formulario 1'!D1157 -> DINA | E6: ='Respuestas de formulario 1'!E1157 -> THQ137 | F6: ='Respuestas de formulario 1'!F1157 -> 86625 | G6: ='Respuestas de formulario 1'!G1157 -> DIURNA | H6: ='Respuestas de formulario 1'!H1157 -> CUMPLE | ... BB6: ='Respuestas de formulario 1'!BB1157 -> No
A7: ='Respuestas de formulario 1'!A1158 -> 45931.288 | B7: ='Respuestas de formulario 1'!B1158 -> Eladio Perdomo Pérez | C7: ='Respuestas de formulario 1'!C1158 -> MANTENIMIENTO (CONSORCIO SAS-CFP) | D7: ='Respuestas de formulario 1'!D1158 -> DINA | E7: ='Respuestas de formulario 1'!E1158 -> THP849 | F7: ='Respuestas de formulario 1'!F1158 -> 133123 | G7: ='Respuestas de formulario 1'!G1158 -> DIURNA | H7: ='Respuestas de formulario 1'!H1158 -> CUMPLE | ... BB7: ='Respuestas de formulario 1'!BB1158 -> No
A8: ='Respuestas de formulario 1'!A1159 -> 45931.29 | B8: ='Respuestas de formulario 1'!B1159 -> Jorge Mosquera | C8: ='Respuestas de formulario 1'!C1159 -> OPERACIÓN | D8: ='Respuestas de formulario 1'!D1159 -> TELLO | E8: ='Respuestas de formulario 1'!E1159 -> NTQ466 | F8: ='Respuestas de formulario 1'!F1159 -> 7280 | G8: ='Respuestas de formulario 1'!G1159 -> DIURNA | H8: ='Respuestas de formulario 1'!H1159 -> CUMPLE | ... BB8: ='Respuestas de formulario 1'!BB1159 -> No
A9: ='Respuestas de formulario 1'!A1160 -> 45931.291 | B9: ='Respuestas de formulario 1'!B1160 -> Willin greey puentes saenz | C9: ='Respuestas de formulario 1'!C1160 -> OPERACIÓN | D9: ='Respuestas de formulario 1'!D1160 -> SAN FRANCISCO | E9: ='Respuestas de formulario 1'!E1160 -> WPT277 | F9: ='Respuestas de formulario 1'!F1160 -> 73744 | G9: ='Respuestas de formulario 1'!G1160 -> DIURNA | H9: ='Respuestas de formulario 1'!H1160 -> CUMPLE | ... BB9: ='Respuestas de formulario 1'!BB1160 -> No
A10: ='Respuestas de formulario 1'!A1161 -> 45931.292 | B10: ='Respuestas de formulario 1'!B1161 -> Aldemar González lasso | C10: ='Respuestas de formulario 1'!C1161 -> MANTENIMIENTO (CONSORCIO SAS-CFP) | D10: ='Respuestas de formulario 1'!D1161 -> SAN FRANCISCO | E10: ='Respuestas de formulario 1'!E1161 -> THS530 | F10: ='Respuestas de formulario 1'!F1161 -> 58349 | G10: ='Respuestas de formulario 1'!G1161 -> DIURNA | H10: ='Respuestas de formulario 1'!H1161 -> CUMPLE | ... BB10: ='Respuestas de formulario 1'!BB1161 -> No
A11: ='Respuestas de formulario 1'!A1162 -> 45931.294 | B11: ='Respuestas de formulario 1'!B1162 -> Wilver Collazos Quiroga | C11: ='Respuestas de formulario 1'!C1162 -> MANTENIMIENTO (CONSORCIO SAS-CFP) | D11: ='Respuestas de formulario 1'!D1162 -> DINA | E11: ='Respuestas de formulario 1'!E1162 -> LPZ104 | F11: ='Respuestas de formulario 1'!F1162 -> 40064 | G11: ='Respuestas de formulario 1'!G1162 -> DIURNA | H11: ='Respuestas de formulario 1'!H1162 -> CUMPLE | ... BB11: ='Respuestas de formulario 1'!BB1162 -> No
A12: ='Respuestas de formulario 1'!A1163 -> 45931.297 | B12: ='Respuestas de formulario 1'!B1163 -> Carlos Andrés Cabrera | C12: ='Respuestas de formulario 1'!C1163 -> OPERACIÓN | D12: ='Respuestas de formulario 1'!D1163 -> SAN FRANCISCO | E12: ='Respuestas de formulario 1'!E1163 -> THQ021 | F12: ='Respuestas de formulario 1'!F1163 -> 94720 | G12: ='Respuestas de formulario 1'!G1163 -> DIURNA | H12: ='Respuestas de formulario 1'!H1163 -> CUMPLE | ... BB12: ='Respuestas de formulario 1'!BB1163 -> No
A13: ='Respuestas de formulario 1'!A1164 -> 45931.299 | B13: ='Respuestas de formulario 1'!B1164 -> Gerardo ariza | C13: ='Respuestas de formulario 1'!C1164 -> MANTENIMIENTO (CONSORCIO SAS-CFP) | D13: ='Respuestas de formulario 1'!D1164 -> DINA | E13: ='Respuestas de formulario 1'!E1164 -> EQZ742 | F13: ='Respuestas de formulario 1'!F1164 -> 99980 | G13: ='Respuestas de formulario 1'!G1164 -> DIURNA | H13: ='Respuestas de formulario 1'!H1164 -> CUMPLE | ... BB13: ='Respuestas de formulario 1'!BB1164 -> No
... A194: ='Respuestas de formulario 1'!A1345 -> 0 | B194: ='Respuestas de formulario 1'!B1345 -> 0 | C194: ='Respuestas de formulario 1'!C1345 -> 0 | D194: ='Respuestas de formulario 1'!D1345 -> 0 | E194: ='Respuestas de formulario 1'!E1345 -> 0 | F194: ='Respuestas de formulario 1'!F1345 -> 0 | G194: ='Respuestas de formulario 1'!G1345 -> 0 | H194: ='Respuestas de formulario 1'!H1345 -> 0 | ... BB194: ='Respuestas de formulario 1'!BB1345 -> 0

Sheet SEPTIEMBRE
A1: Marca temporal | B1: NOMBRE DE QUIEN REALIZA LA INSPECCIÓN | C1: CONTRATO | D1: CAMPO/COORDINACIÓN | E1: PLACA DEL VEHICULO | F1: KILOMETRAJE | G1: TURNO | H1: **Altas y bajas | I1: **Direccionales derecha e izquierda | J1: **De parqueo | K1: **De freno | L1: **De reversa y alarma de retroceso | M1: **Espejo central y espejos laterales | N1: **Vidrio frontal | O1: Presentación de orden y aseo | P1: Pito | Q1: Sistema de monitoreo GPS (Alerta sonora) | R1: **Cinturones de seguridad | S1: Puertas en buen estado | T1: Vidrios en buen estado | U1: Limpia brisas | V1: Exintor vigente | W1: Botiquín | X1: Estado general de tapicería | Y1: Indicadores (nivel de combustible, temperatura, velocímetro y aceite) | Z1: **Verificar la ausencia de objetos sueltos en la cabina que puedan distraer al conductor | AA1: **Frenos | AB1: **Freno de emergencia o de mano | AC1: **Fugas de aire (movil 100) | AD1: **Control fugas de aire (movil 100) | AE1: **Candados y Bandas (movil 100) | AF1: **Acoples para tomas eléctricas y de aire (movil 100) | AG1: **Niveles de fluidos aceite motor | AH1: **Nivel de fluido de frenos | AI1: **Nivel de fluido de dirección hidraúlica | AJ1: **Nivel de fluido refrigerante | AK1: Nivel de fluido limpia parabrisas | AL1: Estado de correas | AM1: Estado de baterías, cables, conexiones | AN1: **Llantas - Labrado (min 3mm de labrado) | AO1: **Llantas - Sin cortaduras y sin abultamientos | AP1: Llanta de repuesto | AQ1: **Copas o pernos de sujeción de las llantas | AR1: **Suspensión (terminales) | AS1: **Dirección (terminales) | AT1: Tapa de tanque de combustible en buen estado | AU1: Equipo de carretera: gato, llave de pernos, herramienta básica, triángulos o conos, bloques, chaleco, señal pare-siga | AV1: Kit ambiental | AW1: Documentación: tecnomecánica y de gases, tarjeta de propiedad, SOAT, licencia de conducción y permiso para conducir interno | AX1: OBSERVACIONES | AY1: ¿Ha dormido al menos 7 horas en las últimas 24 horas? | AZ1: ¿Se encuentra libre de síntomas de fatiga (Somnolencia, dolor de cabeza, irritabilidad)? | BA1: ¿Se siente en condiciones físicas y mentales para conducir? | BB1: ¿Ha consumido medicamentos o sustancias que afecten su estado de alerta?
A2: ='Respuestas de formulario 1'!A658 -> 45901.236 | B2: ='Respuestas de formulario 1'!B658 -> Yoannes Rivas | C2: ='Respuestas de formulario 1'!C658 -> MANTENIMIENTO (CONSORCIO SAS-CFP) | D2: ='Respuestas de formulario 1'!D658 -> SAN FRANCISCO | E2: ='Respuestas de formulario 1'!E658 -> THS530 | F2: ='Respuestas de formulario 1'!F658 -> 56907 | G2: ='Respuestas de formulario 1'!G658 -> DIURNA | H2: ='Respuestas de formulario 1'!H658 -> CUMPLE | ... BB2: ='Respuestas de formulario 1'!BB658 -> No
A3: ='Respuestas de formulario 1'!A659 -> 45901.259 | B3: ='Respuestas de formulario 1'!B659 -> José Leonardo Castro P | C3: ='Respuestas de formulario 1'!C659 -> MANTENIMIENTO (CONSORCIO SAS-CFP) | D3: ='Respuestas de formulario 1'!D659 -> DINA | E3: ='Respuestas de formulario 1'!E659 -> WPT239 | F3: ='Respuestas de formulario 1'!F659 -> 106509 | G3: ='Respuestas de formulario 1'!G659 -> DIURNA | H3: ='Respuestas de formulario 1'!H659 -> CUMPLE | ... BB3: ='Respuestas de formulario 1'!BB659 -> No
A4: ='Respuestas de formulario 1'!A660 -> 45901.261 | B4: ='Respuestas de formulario 1'!B660 -> Carlos Alberto Huepe | C4: ='Respuestas de formulario 1'!C660 -> MANTENIMIENTO (CONSORCIO SAS-CFP) | D4: ='Respuestas de formulario 1'!D660 -> TELLO | E4: ='Respuestas de formulario 1'!E660 -> THS082 | F4: ='Respuestas de formulario 1'!F660 -> 176126 | G4: ='Respuestas de formulario 1'!G660 -> DIURNA | H4: ='Respuestas de formulario 1'!H660 -> CUMPLE | ... BB4: ='Respuestas de formulario 1'!BB660 -> Si, No
A5: ='Respuestas de formulario 1'!A661 -> 45901.262 | B5: ='Respuestas de formulario 1'!B661 -> Arbey trujillo Castro | C5: ='Respuestas de formulario 1'!C661 -> OPERACIÓN | D5: ='Respuestas de formulario 1'!D661 -> YAGUARA | E5: ='Respuestas de formulario 1'!E661 -> Wcz611 | F5: ='Respuestas de formulario 1'!F661 -> 83747 | G5: ='Respuestas de formulario 1'!G661 -> DIURNA | H5: ='Respuestas de formulario 1'!H661 -> CUMPLE | ... BB5: ='Respuestas de formulario 1'!BB661 -> No
A6: ='Respuestas de formulario 1'!A662 -> 45901.272 | B6: ='Respuestas de formulario 1'!B662 -> Jhoan Tamayo Perdomo | C6: ='Respuestas de formulario 1'!C662 -> OPERACIÓN | D6: ='Respuestas de formulario 1'!D662 -> YAGUARA | E6: ='Respuestas de formulario 1'!E662 -> THS412 | F6: ='Respuestas de formulario 1'!F662 -> 38843 | G6: ='Respuestas de formulario 1'!G662 -> NO APLICA | H6: ='Respuestas de formulario 1'!H662 -> CUMPLE | ... BB6: ='Respuestas de formulario 1'!BB662 -> No
A7: ='Respuestas de formulario 1'!A663 -> 45901.281 | B7: ='Respuestas de formulario 1'!B663 -> Jonh edinsson Charry Villarreal | C7: ='Respuestas de formulario 1'!C663 -> OPERACIÓN | D7: ='Respuestas de formulario 1'!D663 -> DINA | E7: ='Respuestas de formulario 1'!E663 -> THQ-137 | F7: ='Respuestas de formulario 1'!F663 -> 85723 | G7: ='Respuestas de formulario 1'!G663 -> DIURNA | H7: ='Respuestas de formulario 1'!H663 -> CUMPLE | ... BB7: ='Respuestas de formulario 1'!BB663 -> No
A8: ='Respuestas de formulario 1'!A664 -> 45901.281 | B8: ='Respuestas de formulario 1'!B664 -> Willin Greey Puentes saenz | C8: ='Respuestas de formulario 1'!C664 -> OPERACIÓN | D8: ='Respuestas de formulario 1'!D664 -> SAN FRANCISCO | E8: ='Respuestas de formulario 1'!E664 -> WPT 277 | F8: ='Respuestas de formulario 1'!F664 -> 72421 | G8: ='Respuestas de formulario 1'!G664 -> DIURNA | H8: ='Respuestas de formulario 1'!H664 -> CUMPLE | ... BB8: ='Respuestas de formulario 1'!BB664 -> No
A9: ='Respuestas de formulario 1'!A665 -> 45901.287 | B9: ='Respuestas de formulario 1'!B665 -> Capitolino mateus | C9: ='Respuestas de formulario 1'!C665 -> MANTENIMIENTO (CONSORCIO SAS-CFP) | D9: ='Respuestas de formulario 1'!D665 -> DINA | E9: ='Respuestas de formulario 1'!E665 -> Eqz286 | F9: ='Respuestas de formulario 1'!F665 -> 97426 | G9: ='Respuestas de formulario 1'!G665 -> DIURNA | H9: ='Respuestas de formulario 1'!H665 -> CUMPLE | ... BB9: ='Respuestas de formulario 1'!BB665 -> No
A10: ='Respuestas de formulario 1'!A666 -> 45901.288 | B10: ='Respuestas de formulario 1'!B666 -> Duvier Alberto Canacue | C10: ='Respuestas de formulario 1'!C666 -> OPERACIÓN | D10: ='Respuestas de formulario 1'!D666 -> SAN FRANCISCO | E10: ='Respuestas de formulario 1'!E666 -> Wpt243 | F10: ='Respuestas de formulario 1'!F666 -> 97374 | G10: ='Respuestas de formulario 1'!G666 -> DIURNA | H10: ='Respuestas de formulario 1'!H666 -> CUMPLE | ... BB10: ='Respuestas de formulario 1'!BB666 -> No
A11: ='Respuestas de formulario 1'!A667 -> 45901.304 | B11: ='Respuestas de formulario 1'!B667 -> Miller Jesús charry | C11: ='Respuestas de formulario 1'!C667 -> OPERACIÓN | D11: ='Respuestas de formulario 1'!D667 -> SAN FRANCISCO | E11: ='Respuestas de formulario 1'!E667 -> THQ 020 | F11: ='Respuestas de formulario 1'!F667 -> 75195 | G11: ='Respuestas de formulario 1'!G667 -> DIURNA | H11: ='Respuestas de formulario 1'!H667 -> CUMPLE | ... BB11: ='Respuestas de formulario 1'!BB667 -> No
A12: ='Respuestas de formulario 1'!A668 -> 45901.325 | B12: ='Respuestas de formulario 1'!B668 -> Jorge Lasso diaz | C12: ='Respuestas de formulario 1'!C668 -> OPERACIÓN | D12: ='Respuestas de formulario 1'!D668 -> DINA | E12: ='Respuestas de formulario 1'!E668 -> THQ 136 | F12: ='Respuestas de formulario 1'!F668 -> 72446 | G12: ='Respuestas de formulario 1'!G668 -> DIURNA | H12: ='Respuestas de formulario 1'!H668 -> CUMPLE | ... BB12: ='Respuestas de formulario 1'!BB668 -> No
A13: ='Respuestas de formulario 1'!A669 -> 45901.331 | B13: ='Respuestas de formulario 1'!B669 -> Gerardo ariza | C13: ='Respuestas de formulario 1'!C669 -> MANTENIMIENTO (CONSORCIO SAS-CFP) | D13: ='Respuestas de formulario 1'!D669 -> DINA | E13: ='Respuestas de formulario 1'!E669 -> EQZ742 | F13: ='Respuestas de formulario 1'!F669 -> 98740 | G13: ='Respuestas de formulario 1'!G669 -> DIURNA | H13: ='Respuestas de formulario 1'!H669 -> CUMPLE | ... BB13: ='Respuestas de formulario 1'!BB669 -> No
... A496: ='Respuestas de formulario 1'!A1152 -> 45930.435 | B496: ='Respuestas de formulario 1'!B1152 -> Jorge Mosquera | C496: ='Respuestas de formulario 1'!C1152 -> OPERACIÓN | D496: ='Respuestas de formulario 1'!D1152 -> TELLO | E496: ='Respuestas de formulario 1'!E1152 -> NTQ466 | F496: ='Respuestas de formulario 1'!F1152 -> 7231 | G496: ='Respuestas de formulario 1'!G1152 -> DIURNA | H496: ='Respuestas de formulario 1'!H1152 -> CUMPLE | ... BB496: ='Respuestas de formulario 1'!BB1152 -> No
